<?xml version="1.0" encoding="UTF-8"?>
<robot name="robot-partial-mesh-getup-no-pelvis">
  <joint name="joint_dof_l_ankle" type="revolute">
    <origin xyz="0. 0.225 0.001" rpy="-0.0000003 0. -3.1415925"/>
    <parent link="left_tibia"/>
    <child link="left_foot"/>
    <axis xyz="0. 0. 1."/>
    <limit lower="-1.5707962" upper="1.5707962" effort="80." velocity="5.0000003"/>
  </joint>
  <joint name="joint_dof_l_elbow" type="revolute">
    <origin xyz="-0.02705 0.01 -0.065 " rpy="1.5707959 -1.3089969 -1.5707958"/>
    <parent link="left_humerus_lower"/>
    <child link="left_radius"/>
    <axis xyz="0. 0. 1."/>
    <limit lower="-0.8901179" upper="1.6580628" effort="80." velocity="5.0000003"/>
  </joint>
  <joint name="joint_dof_l_gripper" type="revolute">
    <origin xyz="0.025 0. -0.032" rpy="1.570796 -0.0000001 -1.5707963"/>
    <parent link="left_gripper_lower"/>
    <child link="left_gripper_upper"/>
    <axis xyz="0. 0. 1."/>
    <limit lower="-1.0471976" upper="0." effort="80." velocity="5.0000003"/>
  </joint>
  <joint name="joint_dof_l_hip_pitch" type="revolute">
    <origin xyz="-0. -0.045 0.0675" rpy="0.4636477 -1.570796 1.1071488"/>
    <parent link="pelvis"/>
    <child link="left_hip"/>
    <axis xyz="0. 0. 1."/>
    <limit lower="-2.6179936" upper="1.5707962" effort="80." velocity="5.0000003"/>
  </joint>
  <joint name="joint_dof_l_hip_roll" type="revolute">
    <origin xyz="-0. -0.025 0.069" rpy="-1.5707963 0. -3.1415925"/>
    <parent link="left_hip"/>
    <child link="left_femur_upper"/>
    <axis xyz="0. 0. 1."/>
    <limit lower="-0.2617994" upper="1.5707962" effort="80." velocity="5.0000003"/>
  </joint>
  <joint name="joint_dof_l_knee" type="revolute">
    <origin xyz="0.03 -0.011 0.09 " rpy="1.5707963 0. 0. "/>
    <parent link="left_femur_lower"/>
    <child link="left_tibia"/>
    <axis xyz="0. 0. 1."/>
    <limit lower="-2.6179936" upper="0.1745329" effort="80." velocity="5.0000003"/>
  </joint>
  <joint name="joint_dof_l_shoulder_pitch" type="revolute">
    <origin xyz="0.0004358 0.0948533 0.2661205" rpy="1.3447376 -0.0196072 3.056552 "/>
    <parent link="alpha_v1_sim_assembly"/>
    <child link="left_shoulder"/>
    <axis xyz="0. 0. 1."/>
    <limit lower="-2.5307271" upper="2.5307271" effort="80." velocity="5.0000003"/>
  </joint>
  <joint name="joint_dof_l_shoulder_roll" type="revolute">
    <origin xyz="-0.02705 -0.018 0.055 " rpy="-1.5707963 0.3839723 1.5707963"/>
    <parent link="left_shoulder"/>
    <child link="left_humerus_upper"/>
    <axis xyz="0. 0. 1."/>
    <limit lower="-0.4101523" upper="2.7052601" effort="80." velocity="5.0000003"/>
  </joint>
  <joint name="joint_dof_l_shoulder_yaw" type="revolute">
    <origin xyz="-0.10955 0.0521805 -0.02705 " rpy="1.5707963 -0.0872665 0.9773841"/>
    <parent link="left_humerus_upper"/>
    <child link="left_humerus_lower"/>
    <axis xyz="0. 0. 1."/>
    <limit lower="-2.7052601" upper="1.134464" effort="80." velocity="5.0000003"/>
  </joint>
  <joint name="joint_dof_l_thigh" type="revolute">
    <origin xyz="-0.15 -0. -0.021" rpy="-3.1415927 1.5707963 0. "/>
    <parent link="left_femur_upper"/>
    <child link="left_femur_lower"/>
    <axis xyz="0. 0. 1."/>
    <limit lower="-2.6179936" upper="1.5707962" effort="80." velocity="5.0000003"/>
  </joint>
  <joint name="joint_dof_l_wrist" type="revolute">
    <origin xyz="-0.0396823 0.1094592 -0.02705 " rpy="1.5707965 -0.0000001 0.2617995"/>
    <parent link="left_radius"/>
    <child link="left_gripper_lower"/>
    <axis xyz="0. 0. 1."/>
    <limit lower="-1.5707962" upper="1.5707962" effort="80." velocity="5.0000003"/>
  </joint>
  <joint name="joint_dof_neck_pitch" type="revolute">
    <origin xyz="0. -0.0252 -0.03 " rpy="-1.5707963 0. 0. "/>
    <parent link="neck"/>
    <child link="head"/>
    <axis xyz="0. 0. 1."/>
    <limit lower="-0.9075711" upper="0.9250244" effort="80." velocity="5.0000003"/>
  </joint>
  <joint name="joint_dof_neck_yaw" type="revolute">
    <origin xyz="0. -0. 0.305" rpy="-3.1415923 0. 0. "/>
    <parent link="alpha_v1_sim_assembly"/>
    <child link="neck"/>
    <axis xyz="0. 0. 1."/>
    <limit lower="-1.3962633" upper="1.3962633" effort="80." velocity="5.0000003"/>
  </joint>
  <joint name="joint_dof_r_ankle" type="revolute">
    <origin xyz="-0. -0.225 0.001" rpy="-0.0000002 0. -3.1415925"/>
    <parent link="right_tibia"/>
    <child link="right_foot"/>
    <axis xyz="0. 0. 1."/>
    <limit lower="-1.5707962" upper="1.5707962" effort="80." velocity="5.0000003"/>
  </joint>
  <joint name="joint_dof_r_elbow" type="revolute">
    <origin xyz="-0.02705 -0.01 -0.065 " rpy="-1.5707957 -1.308997 1.5707958"/>
    <parent link="right_humerus_lower"/>
    <child link="right_radius"/>
    <axis xyz="0. 0. 1."/>
    <limit lower="-1.6580628" upper="0.8901179" effort="80." velocity="5.0000003"/>
  </joint>
  <joint name="joint_dof_r_gripper" type="revolute">
    <origin xyz="0.025 0. -0.032" rpy="1.5707961 0. -1.5707961"/>
    <parent link="right_gripper_lower"/>
    <child link="right_gripper_upper"/>
    <axis xyz="0. 0. 1."/>
    <limit lower="-1.0471976" upper="0." effort="80." velocity="5.0000003"/>
  </joint>
  <joint name="joint_dof_r_hip_pitch" type="revolute">
    <origin xyz="-0. 0.045 0.0675" rpy="1.5707966 -0.0000002 3.1415927"/>
    <parent link="pelvis"/>
    <child link="right_hip"/>
    <axis xyz="0. 0. 1."/>
    <limit lower="-1.5707962" upper="2.6179936" effort="80." velocity="5.0000003"/>
  </joint>
  <joint name="joint_dof_r_hip_roll" type="revolute">
    <origin xyz="-0.025 0. 0.069" rpy="-1.5707963 -0. 1.5707963"/>
    <parent link="right_hip"/>
    <child link="right_femur_upper"/>
    <axis xyz="0. 0. 1."/>
    <limit lower="-1.5707962" upper="0.2617994" effort="80." velocity="5.0000003"/>
  </joint>
  <joint name="joint_dof_r_knee" type="revolute">
    <origin xyz="0.03 0.011 0.09 " rpy="-1.5707963 0. 0. "/>
    <parent link="right_femur_lower"/>
    <child link="right_tibia"/>
    <axis xyz="0. 0. 1."/>
    <limit lower="-0.1745329" upper="2.6179936" effort="80." velocity="5.0000003"/>
  </joint>
  <joint name="joint_dof_r_shoulder_pitch" type="revolute">
    <origin xyz="0.0004358 -0.0948533 0.2661205" rpy="-1.344738 -0.0196067 -3.056552 "/>
    <parent link="alpha_v1_sim_assembly"/>
    <child link="right_shoulder"/>
    <axis xyz="0. 0. 1."/>
    <limit lower="-2.5307271" upper="2.5307271" effort="80." velocity="5.0000003"/>
  </joint>
  <joint name="joint_dof_r_shoulder_roll" type="revolute">
    <origin xyz="-0.02705 0.018 0.055 " rpy="1.5707963 0.3839723 -1.5707963"/>
    <parent link="right_shoulder"/>
    <child link="right_humerus_upper"/>
    <axis xyz="0. 0. 1."/>
    <limit lower="-2.7052601" upper="0.1745329" effort="80." velocity="5.0000003"/>
  </joint>
  <joint name="joint_dof_r_shoulder_yaw" type="revolute">
    <origin xyz="-0.10955 -0.0521805 -0.02705 " rpy="-1.5707965 -0.0872663 -0.9773841"/>
    <parent link="right_humerus_upper"/>
    <child link="right_humerus_lower"/>
    <axis xyz="0. 0. 1."/>
    <limit lower="-0.959931" upper="2.8797933" effort="80." velocity="5.0000003"/>
  </joint>
  <joint name="joint_dof_r_thigh" type="revolute">
    <origin xyz="0.15 -0. -0.021" rpy="0.0000001 1.5707963 0. "/>
    <parent link="right_femur_upper"/>
    <child link="right_femur_lower"/>
    <axis xyz="0. 0. 1."/>
    <limit lower="-1.5707962" upper="2.6179936" effort="80." velocity="5.0000003"/>
  </joint>
  <joint name="joint_dof_r_wrist" type="revolute">
    <origin xyz="-0.0396823 -0.1094592 -0.02705 " rpy="1.5707964 0.0000002 2.8797932"/>
    <parent link="right_radius"/>
    <child link="right_gripper_lower"/>
    <axis xyz="0. 0. 1."/>
    <limit lower="-1.5707962" upper="1.5707962" effort="80." velocity="5.0000003"/>
  </joint>
  <joint name="joint_dof_waist" type="revolute">
    <origin xyz="0. 0. 0." rpy="-3.1415925 0. 0. "/>
    <parent link="alpha_v1_sim_assembly"/>
    <child link="pelvis"/>
    <axis xyz="0. 0. 1."/>
    <limit lower="-1.0471976" upper="1.0471976" effort="80." velocity="5.0000003"/>
  </joint>
  <link name="alpha_v1_sim_assembly">
    <visual>
      <origin xyz="0. 0. 0." rpy="0. 0. 0."/>
      <geometry>
        <mesh filename="meshes/torso_visuals_mesh_0.obj" scale="1. 1. 1."/>
      </geometry>
    </visual>
    <visual>
      <origin xyz="0. 0. 0." rpy="-3.1415925 0. 0. "/>
      <geometry>
        <mesh filename="meshes/torso_visuals_mesh_1.obj" scale="1. 1. 1."/>
      </geometry>
    </visual>
    <visual>
      <origin xyz="0. -0. 0.005" rpy="-3.1415925 0. 0. "/>
      <geometry>
        <mesh filename="meshes/torso_visuals_mesh_2.obj" scale="1. 1. 1."/>
      </geometry>
    </visual>
    <visual>
      <origin xyz="0. -0. 0.005" rpy="-3.1415925 0. 0. "/>
      <geometry>
        <mesh filename="meshes/torso_visuals_mesh_3.obj" scale="1. 1. 1."/>
      </geometry>
    </visual>
    <visual>
      <origin xyz="0. -0. 0.2995" rpy="0. 0. 0."/>
      <geometry>
        <mesh filename="meshes/torso_visuals_mesh_4.obj" scale="1. 1. 1."/>
      </geometry>
    </visual>
    <visual>
      <origin xyz="0. -0. 0.3015" rpy="-3.1415925 0. 0. "/>
      <geometry>
        <mesh filename="meshes/torso_visuals_mesh_5.obj" scale="1. 1. 1."/>
      </geometry>
    </visual>
    <visual>
      <origin xyz="0. -0. 0.2965" rpy="0. 0. 0."/>
      <geometry>
        <mesh filename="meshes/torso_visuals_mesh_6.obj" scale="1. 1. 1."/>
      </geometry>
    </visual>
    <visual>
      <origin xyz="-0.004 -0.062 0.1075" rpy="0.8436348 -1.5707961 -0.8436349"/>
      <geometry>
        <mesh filename="meshes/torso_visuals_mesh_7.obj" scale="1. 1. 1."/>
      </geometry>
    </visual>
    <visual>
      <origin xyz="-0.004 0.042 0.0355" rpy="-2.079953 1.5707961 1.0616398"/>
      <geometry>
        <mesh filename="meshes/torso_visuals_mesh_8.obj" scale="1. 1. 1."/>
      </geometry>
    </visual>
    <visual>
      <origin xyz="0. 0.09 0.265" rpy="-1.3447378 0.019607 -0.0850408"/>
      <geometry>
        <mesh filename="meshes/torso_visuals_mesh_9.obj" scale="1. 1. 1."/>
      </geometry>
    </visual>
    <visual>
      <origin xyz="0. 0.09 0.265" rpy="-1.3447378 0.019607 -0.0850408"/>
      <geometry>
        <mesh filename="meshes/torso_visuals_mesh_10.obj" scale="1. 1. 1."/>
      </geometry>
    </visual>
    <visual>
      <origin xyz="0.009 -0.078 0.1995" rpy="-1.5707964 -0.0000002 1.5707963"/>
      <geometry>
        <mesh filename="meshes/mesh_11.obj" scale="1. 1. 1."/>
      </geometry>
    </visual>
    <visual>
      <origin xyz="0.009 -0.025 0.2165" rpy="1.5707964 0.0000002 -1.5707961"/>
      <geometry>
        <mesh filename="meshes/mesh_12.obj" scale="1. 1. 1."/>
      </geometry>
    </visual>
    <visual>
      <origin xyz="-0.008 -0.06 0.019" rpy="1.5707964 -0.0000002 1.5707961"/>
      <geometry>
        <mesh filename="meshes/torso_visuals_mesh_13.obj" scale="1. 1. 1."/>
      </geometry>
    </visual>
    <visual>
      <origin xyz="-0.0693389 -0. 0.3009603" rpy="-3.1415925 -1.2027266 -0.0000003"/>
      <geometry>
        <mesh filename="meshes/mesh_14.obj" scale="1. 1. 1."/>
      </geometry>
    </visual>
    <visual>
      <origin xyz="-0.0694383 0.0269575 0.301149 " rpy="-1.9294804 -0.0225055 -1.6077669"/>
      <geometry>
        <mesh filename="meshes/mesh_15.obj" scale="1. 1. 1."/>
      </geometry>
    </visual>
    <visual>
      <origin xyz="0.0005 -0.0950111 0.0190997" rpy="-1.570796 -0.0000002 1.5707961"/>
      <geometry>
        <mesh filename="meshes/torso_visuals_mesh_16.obj" scale="1. 1. 1."/>
      </geometry>
    </visual>
    <visual>
      <origin xyz="-0.0032 -0.0399142 0.0869434" rpy="1.5707964 -0.0000002 1.5707961"/>
      <geometry>
        <mesh filename="meshes/mesh_17.obj" scale="1. 1. 1."/>
      </geometry>
    </visual>
    <visual>
      <origin xyz="-0.0817 -0.0004142 0.1515496" rpy="1.5707964 -0.0000002 1.5707961"/>
      <geometry>
        <mesh filename="meshes/mesh_18.obj" scale="1. 1. 1."/>
      </geometry>
    </visual>
    <visual>
      <origin xyz="-0.0919 -0.0004142 0.1522248" rpy="1.5707964 -0.0000002 1.5707961"/>
      <geometry>
        <mesh filename="meshes/mesh_19.obj" scale="1. 1. 1."/>
      </geometry>
    </visual>
    <visual>
      <origin xyz="-0.0400156 0.0625 0.2950109" rpy="0.0000003 -1.2027267 -0.0000002"/>
      <geometry>
        <mesh filename="meshes/mesh_20.obj" scale="1. 1. 1."/>
      </geometry>
    </visual>
    <visual>
      <origin xyz="-0.0759303 -0. 0.0649434" rpy="1.5707964 -0.0000002 1.5707961"/>
      <geometry>
        <mesh filename="meshes/torso_visuals_mesh_21.obj" scale="1. 1. 1."/>
      </geometry>
    </visual>
    <visual>
      <origin xyz="-0.0694383 -0.0269575 0.301149 " rpy="-2.811537 -1.1907353 -0.3080155"/>
      <geometry>
        <mesh filename="meshes/mesh_22.obj" scale="1. 1. 1."/>
      </geometry>
    </visual>
    <visual>
      <origin xyz="-0.0559303 -0.0206501 0.2788047" rpy="1.5707964 0.0000004 -1.5707964"/>
      <geometry>
        <mesh filename="meshes/mesh_23.obj" scale="1. 1. 1."/>
      </geometry>
    </visual>
    <visual>
      <origin xyz="-0.0087219 -0.0203291 0.2179434" rpy="3.1415927 -0. -1.5707964"/>
      <geometry>
        <mesh filename="meshes/mesh_24.obj" scale="1. 1. 1."/>
      </geometry>
    </visual>
    <visual>
      <origin xyz="-0.0400156 -0.0625 0.2950108" rpy="0.0000003 -1.2027267 -0.0000002"/>
      <geometry>
        <mesh filename="meshes/mesh_25.obj" scale="1. 1. 1."/>
      </geometry>
    </visual>
    <visual>
      <origin xyz="-0.0619303 -0.02635 0.2725465" rpy="1.715257 1.5707961 1.715257 "/>
      <geometry>
        <mesh filename="meshes/mesh_26.obj" scale="1. 1. 1."/>
      </geometry>
    </visual>
    <visual>
      <origin xyz="0. -0.09 0.265" rpy="-1.344738 -0.019607 -3.056552"/>
      <geometry>
        <mesh filename="meshes/mesh_27.obj" scale="1. 1. 1."/>
      </geometry>
    </visual>
    <visual>
      <origin xyz="0. -0.09 0.265" rpy="1.3447381 0.0196069 0.0850408"/>
      <geometry>
        <mesh filename="meshes/mesh_28.obj" scale="1. 1. 1."/>
      </geometry>
    </visual>
    <collision>
      <origin xyz="-0.008 -0.06 0.019" rpy="1.5707964 -0.0000002 1.5707961"/>
      <geometry>
        <mesh filename="meshes/torso_collisions_mesh_13.obj" scale="1. 1. 1."/>
      </geometry>
    </collision>
    <collision>
      <origin xyz="0.0005 -0.0950111 0.0190997" rpy="-1.570796 -0.0000002 1.5707961"/>
      <geometry>
        <mesh filename="meshes/torso_collisions_mesh_16.obj" scale="1. 1. 1."/>
      </geometry>
    </collision>
    <collision>
      <origin xyz="-0.0759303 -0. 0.0649434" rpy="1.5707964 -0.0000002 1.5707961"/>
      <geometry>
        <mesh filename="meshes/torso_collisions_mesh_21.obj" scale="1. 1. 1."/>
      </geometry>
    </collision>
  </link>
  <link name="head">
    <inertial>
      <origin xyz="0.0298701 0.0338731 0.0314461" rpy="0. 0. 0."/>
      <mass value="0.7710117"/>
      <inertia ixx="0.0031279" ixy="0.0000162" ixz="0.0000251" iyy="0.0021968" iyz="-0.0002063" izz="0.001348"/>
    </inertial>
    <visual>
      <origin xyz="0. -0. -0." rpy="0. 0. 0."/>
      <geometry>
        <mesh filename="meshes/head_visuals_mesh_0.obj" scale="1. 1. 1."/>
      </geometry>
    </visual>
    <visual>
      <origin xyz="0. -0. 0.0538" rpy="0. 0. 0."/>
      <geometry>
        <mesh filename="meshes/head_visuals_mesh_1.obj" scale="1. 1. 1."/>
      </geometry>
    </visual>
    <visual>
      <origin xyz="0.0122581 0.03475 0.04235 " rpy="1.2140217 1.5707963 -0.3567746"/>
      <geometry>
        <mesh filename="meshes/head_visuals_mesh_2.obj" scale="1. 1. 1."/>
      </geometry>
    </visual>
    <visual>
      <origin xyz="-0.0336212 0.0238337 -0.0098 " rpy="1.538018 1.5707963 -0.0676848"/>
      <geometry>
        <mesh filename="meshes/head_visuals_mesh_3.obj" scale="1. 1. 1."/>
      </geometry>
    </visual>
    <visual>
      <origin xyz="0.0426902 0.0500512 -0.0348 " rpy="1.2140217 1.5707963 -0.3567746"/>
      <geometry>
        <mesh filename="meshes/head_visuals_mesh_4.obj" scale="1. 1. 1."/>
      </geometry>
    </visual>
    <visual>
      <origin xyz="0.0031954 0.0520512 0.0252 " rpy="-1.1670002 1.5707963 0.403796 "/>
      <geometry>
        <mesh filename="meshes/head_visuals_mesh_5.obj" scale="1. 1. 1."/>
      </geometry>
    </visual>
    <visual>
      <origin xyz="-0.0088412 0.0587658 0.0877948" rpy="3.1415923 1.2094293 1.1482929"/>
      <geometry>
        <mesh filename="meshes/head_visuals_mesh_6.obj" scale="1. 1. 1."/>
      </geometry>
    </visual>
    <visual>
      <origin xyz="-0.0253197 0.0586438 0.1002 " rpy="1.6676418 1.5707963 0.0793923"/>
      <geometry>
        <mesh filename="meshes/head_visuals_mesh_7.obj" scale="1. 1. 1."/>
      </geometry>
    </visual>
    <visual>
      <origin xyz="0.0738837 0.0196248 0.0432 " rpy="1.2140217 1.5707963 -0.3567746"/>
      <geometry>
        <mesh filename="meshes/head_visuals_mesh_8.obj" scale="1. 1. 1."/>
      </geometry>
    </visual>
  </link>
  <link name="left_femur_lower">
    <inertial>
      <origin xyz="0.0081732 -0.0128812 0.0524965" rpy="0. 0. 0."/>
      <mass value="0.2734313"/>
      <inertia ixx="0.0005084" ixy="-0.0000206" ixz="-0.0000633" iyy="0.0004956" iyz="0.0000967" izz="0.000429"/>
    </inertial>
    <visual>
      <origin xyz="0. 0. 0." rpy="0. 0. 0."/>
      <geometry>
        <mesh filename="meshes/left_femur_lower_visuals_mesh_0.obj" scale="1. 1. 1."/>
      </geometry>
    </visual>
    <visual>
      <origin xyz="0. 0. 0." rpy="0. 0. 0."/>
      <geometry>
        <mesh filename="meshes/left_femur_lower_visuals_mesh_1.obj" scale="1. 1. 1."/>
      </geometry>
    </visual>
  </link>
  <link name="left_femur_upper">
    <inertial>
      <origin xyz="-0.0495489 -0.0002482 -0.0250827" rpy="0. 0. 0."/>
      <mass value="1.5005854"/>
      <inertia ixx="0.0014659" ixy="-0.0000699" ixz="-0.0000062" iyy="0.0061365" iyz="-0.00001" izz="0.0058611"/>
    </inertial>
    <visual>
      <origin xyz="-0. 0. 0." rpy="0. 0. -0."/>
      <geometry>
        <mesh filename="meshes/left_femur_upper_visuals_mesh_0.obj" scale="1. 1. 1."/>
      </geometry>
    </visual>
    <visual>
      <origin xyz="-0. 0. -0.009" rpy="-0. 0. -1.5707963"/>
      <geometry>
        <mesh filename="meshes/left_femur_upper_visuals_mesh_1.obj" scale="1. 1. 1."/>
      </geometry>
    </visual>
    <visual>
      <origin xyz="-0.145 -0. -0.021" rpy="0.5852171 -1.5707961 -0.5852171"/>
      <geometry>
        <mesh filename="meshes/left_femur_upper_visuals_mesh_2.obj" scale="1. 1. 1."/>
      </geometry>
    </visual>
    <visual>
      <origin xyz="-0.145 -0. -0.021" rpy="0.5852171 -1.5707961 -0.5852171"/>
      <geometry>
        <mesh filename="meshes/left_femur_upper_visuals_mesh_3.obj" scale="1. 1. 1."/>
      </geometry>
    </visual>
    <visual>
      <origin xyz="-0. 0. -0.009" rpy="0. 0. -0."/>
      <geometry>
        <mesh filename="meshes/left_femur_upper_visuals_mesh_4.obj" scale="1. 1. 1."/>
      </geometry>
    </visual>
    <visual>
      <origin xyz="-0. 0. -0.009" rpy="-0. 0. -1.5707963"/>
      <geometry>
        <mesh filename="meshes/left_femur_upper_visuals_mesh_5.obj" scale="1. 1. 1."/>
      </geometry>
    </visual>
    <collision>
      <origin xyz="-0. 0. -0.009" rpy="0. 0. -0."/>
      <geometry>
        <mesh filename="meshes/left_femur_upper_collisions_mesh_4.obj" scale="1. 1. 1."/>
      </geometry>
    </collision>
  </link>
  <link name="left_foot">
    <inertial>
      <origin xyz="0.0186991 -0.058262 -0.00597 " rpy="0. 0. 0."/>
      <mass value="0.3716068"/>
      <inertia ixx="0.0007259" ixy="-0.0001384" ixz="-0.0000031" iyy="0.0005977" iyz="0.0000503" izz="0.0006207"/>
    </inertial>
    <visual>
      <origin xyz="0. -0. -0." rpy="-0.0000003 0. 0. "/>
      <geometry>
        <mesh filename="meshes/left_foot_visuals_mesh_0.obj" scale="1. 1. 1."/>
      </geometry>
    </visual>
    <visual>
      <origin xyz="0.057 -0.066 -0.012" rpy="-2.7071614 1.5707961 -1.1363653"/>
      <geometry>
        <mesh filename="meshes/left_foot_visuals_mesh_1.obj" scale="1. 1. 1."/>
      </geometry>
    </visual>
    <visual>
      <origin xyz="-0.039 -0.069 -0.012" rpy="-2.7071614 1.5707961 -1.1363653"/>
      <geometry>
        <mesh filename="meshes/left_foot_visuals_mesh_2.obj" scale="1. 1. 1."/>
      </geometry>
    </visual>
    <visual>
      <origin xyz="-0.039 -0.072 -0.012" rpy="-2.7071614 1.5707961 -1.1363653"/>
      <geometry>
        <mesh filename="meshes/left_foot_visuals_mesh_3.obj" scale="1. 1. 1."/>
      </geometry>
    </visual>
    <collision>
      <origin xyz="-0.039 -0.072 -0.012" rpy="-2.7071614 1.5707961 -1.1363653"/>
      <geometry>
        <mesh filename="meshes/left_foot_collisions_mesh_3.obj" scale="1. 1. 1."/>
      </geometry>
    </collision>
  </link>
  <link name="left_gripper_lower">
    <inertial>
      <origin xyz="0.0017305 -0.0059832 -0.0356482" rpy="0. 0. 0."/>
      <mass value="0.4099009"/>
      <inertia ixx="0.0002768" ixy="-0.0000573" ixz="0.0000295" iyy="0.0002508" iyz="0.0000031" izz="0.0002637"/>
    </inertial>
    <visual>
      <origin xyz="-0. 0. -0." rpy="-0.0000001 0.0000002 0. "/>
      <geometry>
        <mesh filename="meshes/left_gripper_lower_visuals_mesh_0.obj" scale="1. 1. 1."/>
      </geometry>
    </visual>
    <visual>
      <origin xyz="0.0107 -0.0139599 -0.0512142" rpy="1.570796 -0.0000001 -1.5707961"/>
      <geometry>
        <mesh filename="meshes/left_gripper_lower_visuals_mesh_1.obj" scale="1. 1. 1."/>
      </geometry>
    </visual>
    <visual>
      <origin xyz="-0.0184 0.0139599 -0.0512142" rpy="1.570796 -0.0000001 -1.5707961"/>
      <geometry>
        <mesh filename="meshes/left_gripper_lower_visuals_mesh_2.obj" scale="1. 1. 1."/>
      </geometry>
    </visual>
    <visual>
      <origin xyz="-0.0184 0. -0.032 " rpy="-1.5707965 -0. -1.5707961"/>
      <geometry>
        <mesh filename="meshes/left_gripper_lower_visuals_mesh_3.obj" scale="1. 1. 1."/>
      </geometry>
    </visual>
    <visual>
      <origin xyz="-0.0199 -0. -0.032 " rpy="-1.5707965 -0. -1.5707961"/>
      <geometry>
        <mesh filename="meshes/left_gripper_lower_visuals_mesh_4.obj" scale="1. 1. 1."/>
      </geometry>
    </visual>
    <visual>
      <origin xyz="-0.0199 -0. -0.032 " rpy="1.5707964 -0.0000001 -1.5707963"/>
      <geometry>
        <mesh filename="meshes/left_gripper_lower_visuals_mesh_5.obj" scale="1. 1. 1."/>
      </geometry>
    </visual>
    <visual>
      <origin xyz="-0.0219 -0. -0.032 " rpy="-1.5707963 -0.0000001 -1.5707961"/>
      <geometry>
        <mesh filename="meshes/left_gripper_lower_visuals_mesh_6.obj" scale="1. 1. 1."/>
      </geometry>
    </visual>
    <visual>
      <origin xyz="-0.0239 0. -0.032 " rpy="-1.5707965 -0. -1.5707961"/>
      <geometry>
        <mesh filename="meshes/left_gripper_lower_visuals_mesh_7.obj" scale="1. 1. 1."/>
      </geometry>
    </visual>
    <visual>
      <origin xyz="0.0205 0. -0.032 " rpy="1.570796 -0.0000001 -1.5707961"/>
      <geometry>
        <mesh filename="meshes/left_gripper_lower_visuals_mesh_8.obj" scale="1. 1. 1."/>
      </geometry>
    </visual>
    <visual>
      <origin xyz="-0. -0.0333672 -0.0706747" rpy="-1.6231563 0.0000002 0. "/>
      <geometry>
        <mesh filename="meshes/left_gripper_lower_visuals_mesh_9.obj" scale="1. 1. 1."/>
      </geometry>
    </visual>
    <visual>
      <origin xyz="-0.0149082 -0.0347293 -0.092864 " rpy="-3.0499606 0.0000002 0. "/>
      <geometry>
        <mesh filename="meshes/left_gripper_lower_visuals_mesh_10.obj" scale="1. 1. 1."/>
      </geometry>
    </visual>
    <collision>
      <origin xyz="-0. -0.0333672 -0.0706747" rpy="-1.6231563 0.0000002 0. "/>
      <geometry>
        <mesh filename="meshes/left_gripper_lower_collisions_mesh_9.obj" scale="1. 1. 1."/>
      </geometry>
    </collision>
  </link>
  <link name="left_gripper_upper">
    <inertial>
      <origin xyz="-0.0178005 -0.0462068 0.0246915" rpy="0. 0. 0."/>
      <mass value="0.2071514"/>
      <inertia ixx="0.0002307" ixy="-0.0000006" ixz="0.0000126" iyy="0.0001534" iyz="-0.0000533" izz="0.0002495"/>
    </inertial>
    <visual>
      <origin xyz="0. -0. -0." rpy="0.0000003 -0. -0. "/>
      <geometry>
        <mesh filename="meshes/left_gripper_upper_visuals_mesh_0.obj" scale="1. 1. 1."/>
      </geometry>
    </visual>
    <visual>
      <origin xyz="-0.0278173 -0.0552397 0.025 " rpy="0.8131771 1.570796 0.98771 "/>
      <geometry>
        <mesh filename="meshes/left_gripper_upper_visuals_mesh_1.obj" scale="1. 1. 1."/>
      </geometry>
    </visual>
    <visual>
      <origin xyz="-0.0205461 -0.0684639 0.0559893" rpy="3.141591 1.4541256 1.8515396"/>
      <geometry>
        <mesh filename="meshes/left_gripper_upper_visuals_mesh_2.obj" scale="1. 1. 1."/>
      </geometry>
    </visual>
    <collision>
      <origin xyz="-0.0278173 -0.0552397 0.025 " rpy="0.8131771 1.570796 0.98771 "/>
      <geometry>
        <mesh filename="meshes/left_gripper_upper_collisions_mesh_1.obj" scale="1. 1. 1."/>
      </geometry>
    </collision>
  </link>
  <link name="left_hip">
    <inertial>
      <origin xyz="0. -0.0187376 0.0289007" rpy="0. 0. 0."/>
      <mass value="0.1824669"/>
      <inertia ixx="0.0001051" ixy="0." ixz="-0.0000443" iyy="0.0001826" iyz="0." izz="0.0001759"/>
    </inertial>
    <visual>
      <origin xyz="-0. 0. 0." rpy="0. -0. -0."/>
      <geometry>
        <mesh filename="meshes/left_hip_visuals.obj" scale="1. 1. 1."/>
      </geometry>
    </visual>
  </link>
  <link name="left_humerus_lower">
    <inertial>
      <origin xyz="-0.0003666 0.0009016 -0.0328147" rpy="0. 0. 0."/>
      <mass value="0.109223"/>
      <inertia ixx="0.0000954" ixy="-0.0000003" ixz="-0.0000091" iyy="0.0001305" iyz="0.0000029" izz="0.0000878"/>
    </inertial>
    <visual>
      <origin xyz="0. 0. 0." rpy="0. 0. 0."/>
      <geometry>
        <mesh filename="meshes/left_humerus_lower_visuals_mesh_0.obj" scale="1. 1. 1."/>
      </geometry>
    </visual>
    <visual>
      <origin xyz="0. 0. 0." rpy="-0. -0. -3.1415925"/>
      <geometry>
        <mesh filename="meshes/left_humerus_lower_visuals_mesh_1.obj" scale="1. 1. 1."/>
      </geometry>
    </visual>
  </link>
  <link name="left_humerus_upper">
    <inertial>
      <origin xyz="-0.0449732 0.0170751 -0.0262619" rpy="0. 0. 0."/>
      <mass value="0.9145328"/>
      <inertia ixx="0.0021568" ixy="0.0002941" ixz="-0.0000261" iyy="0.0005077" iyz="0.0001712" izz="0.0021913"/>
    </inertial>
    <visual>
      <origin xyz="0. 0. -0." rpy="-0.0000001 -0.0000001 -0. "/>
      <geometry>
        <mesh filename="meshes/left_humerus_upper_visuals_mesh_0.obj" scale="1. 1. 1."/>
      </geometry>
    </visual>
    <visual>
      <origin xyz="0. 0. -0." rpy="-0. -0.0000001 -0.2094391"/>
      <geometry>
        <mesh filename="meshes/left_humerus_upper_visuals_mesh_1.obj" scale="1. 1. 1."/>
      </geometry>
    </visual>
    <visual>
      <origin xyz="-0.0497764 0.0118627 -0.02705 " rpy="-2.8504827 1.5707961 -0.3023022"/>
      <geometry>
        <mesh filename="meshes/left_humerus_upper_visuals_mesh_2.obj" scale="1. 1. 1."/>
      </geometry>
    </visual>
    <visual>
      <origin xyz="-0.0497764 0.0118627 -0.02705 " rpy="-1.570796 -0. -2.1642084"/>
      <geometry>
        <mesh filename="meshes/left_humerus_upper_visuals_mesh_3.obj" scale="1. 1. 1."/>
      </geometry>
    </visual>
    <visual>
      <origin xyz="-0.0705023 0.0258425 -0.02705 " rpy="-3.0131352 1.570796 -0.4649547"/>
      <geometry>
        <mesh filename="meshes/left_humerus_upper_visuals_mesh_4.obj" scale="1. 1. 1."/>
      </geometry>
    </visual>
    <visual>
      <origin xyz="-0.103498 0.0480984 -0.02705 " rpy="-3.0131352 1.570796 -0.4649547"/>
      <geometry>
        <mesh filename="meshes/left_humerus_upper_visuals_mesh_5.obj" scale="1. 1. 1."/>
      </geometry>
    </visual>
    <visual>
      <origin xyz="-0.0497764 0.0118627 -0.02705 " rpy="-2.8504827 1.5707961 -0.3023022"/>
      <geometry>
        <mesh filename="meshes/left_humerus_upper_visuals_mesh_6.obj" scale="1. 1. 1."/>
      </geometry>
    </visual>
    <visual>
      <origin xyz="-0.0497764 0.0118627 -0.02705 " rpy="-2.2529604 -1.5707961 1.6595485"/>
      <geometry>
        <mesh filename="meshes/left_humerus_upper_visuals_mesh_7.obj" scale="1. 1. 1."/>
      </geometry>
    </visual>
    <visual>
      <origin xyz="0. 0. -0." rpy="-0. -0.0000001 -0.2094391"/>
      <geometry>
        <mesh filename="meshes/left_humerus_upper_visuals_mesh_8.obj" scale="1. 1. 1."/>
      </geometry>
    </visual>
    <visual>
      <origin xyz="0. 0. -0." rpy="-0. -0.0000001 -0.2094391"/>
      <geometry>
        <mesh filename="meshes/left_humerus_upper_visuals_mesh_9.obj" scale="1. 1. 1."/>
      </geometry>
    </visual>
  </link>
  <link name="left_radius">
    <inertial>
      <origin xyz="-0.0150002 0.0355852 -0.0260632" rpy="0. 0. 0."/>
      <mass value="0.7779893"/>
      <inertia ixx="0.0016945" ixy="0.0001715" ixz="-0.0000084" iyy="0.0003639" iyz="0.0000857" izz="0.0017194"/>
    </inertial>
    <visual>
      <origin xyz="-0. -0. -0." rpy="0.0000001 -0. -0. "/>
      <geometry>
        <mesh filename="meshes/left_radius_visuals_mesh_0.obj" scale="1. 1. 1."/>
      </geometry>
    </visual>
    <visual>
      <origin xyz="-0. -0. -0." rpy="0.0000001 0. -1.0471976"/>
      <geometry>
        <mesh filename="meshes/left_radius_visuals_mesh_1.obj" scale="1. 1. 1."/>
      </geometry>
    </visual>
    <visual>
      <origin xyz="-0.021979 0.0433899 -0.02705 " rpy="-1.8325958 1.5707963 0. "/>
      <geometry>
        <mesh filename="meshes/left_radius_visuals_mesh_2.obj" scale="1. 1. 1."/>
      </geometry>
    </visual>
    <visual>
      <origin xyz="-0.021979 0.0433899 -0.02705 " rpy="1.8325958 -1.5707963 0. "/>
      <geometry>
        <mesh filename="meshes/left_radius_visuals_mesh_3.obj" scale="1. 1. 1."/>
      </geometry>
    </visual>
    <visual>
      <origin xyz="-0.021979 0.0433899 -0.02705 " rpy="1.9064469 1.5707961 0.59745 "/>
      <geometry>
        <mesh filename="meshes/left_radius_visuals_mesh_4.obj" scale="1. 1. 1."/>
      </geometry>
    </visual>
    <visual>
      <origin xyz="-0.0284495 0.067538 -0.02705 " rpy="1.5707963 0.0000002 -2.8797932"/>
      <geometry>
        <mesh filename="meshes/left_radius_visuals_mesh_5.obj" scale="1. 1. 1."/>
      </geometry>
    </visual>
    <visual>
      <origin xyz="-0.0359812 0.0956465 -0.02705 " rpy="1.6025883 1.5707961 0.2935914"/>
      <geometry>
        <mesh filename="meshes/left_radius_visuals_mesh_6.obj" scale="1. 1. 1."/>
      </geometry>
    </visual>
    <visual>
      <origin xyz="-0.021979 0.0433899 -0.02705 " rpy="1.1316489 -1.5707963 -2.440646 "/>
      <geometry>
        <mesh filename="meshes/left_radius_visuals_mesh_7.obj" scale="1. 1. 1."/>
      </geometry>
    </visual>
    <visual>
      <origin xyz="-0. -0. -0." rpy="0.0000001 0. -1.0471976"/>
      <geometry>
        <mesh filename="meshes/left_radius_visuals_mesh_8.obj" scale="1. 1. 1."/>
      </geometry>
    </visual>
    <visual>
      <origin xyz="-0. -0. -0." rpy="0.0000001 0. -1.0471976"/>
      <geometry>
        <mesh filename="meshes/left_radius_visuals_mesh_9.obj" scale="1. 1. 1."/>
      </geometry>
    </visual>
    <collision>
      <origin xyz="-0. -0. -0." rpy="0.0000001 0. -1.0471976"/>
      <geometry>
        <mesh filename="meshes/left_radius_collisions_mesh_8.obj" scale="1. 1. 1."/>
      </geometry>
    </collision>
  </link>
  <link name="left_shoulder">
    <inertial>
      <origin xyz="-0.000334 -0.0069263 0.0280464" rpy="0. 0. 0."/>
      <mass value="0.1048731"/>
      <inertia ixx="0.0000817" ixy="-0.0000053" ixz="0.0000131" iyy="0.0001173" iyz="0.0000156" izz="0.0000927"/>
    </inertial>
    <visual>
      <origin xyz="0. 0. 0." rpy="0. 0. 0."/>
      <geometry>
        <mesh filename="meshes/left_shoulder_visuals_mesh_0.obj" scale="1. 1. 1."/>
      </geometry>
    </visual>
    <visual>
      <origin xyz="0. 0. 0." rpy="-3.1415925 0. 0. "/>
      <geometry>
        <mesh filename="meshes/left_shoulder_visuals_mesh_1.obj" scale="1. 1. 1."/>
      </geometry>
    </visual>
  </link>
  <link name="left_tibia">
    <inertial>
      <origin xyz="0.0002236 0.1132651 -0.0181919" rpy="0. 0. 0."/>
      <mass value="1.7307785"/>
      <inertia ixx="0.0016898" ixy="-0.0008769" ixz="-0.0002367" iyy="0.0199925" iyz="-0.0000222" izz="0.0205278"/>
    </inertial>
    <visual>
      <origin xyz="0. 0. 0." rpy="-0. 0. 0."/>
      <geometry>
        <mesh filename="meshes/left_tibia_visuals_mesh_0.obj" scale="1. 1. 1."/>
      </geometry>
    </visual>
    <visual>
      <origin xyz="0. 0. -0.003" rpy="-0. 0. 0."/>
      <geometry>
        <mesh filename="meshes/left_tibia_visuals_mesh_1.obj" scale="1. 1. 1."/>
      </geometry>
    </visual>
    <visual>
      <origin xyz="0. 0. -0.0327" rpy="-3.1415925 0. 0. "/>
      <geometry>
        <mesh filename="meshes/left_tibia_visuals_mesh_2.obj" scale="1. 1. 1."/>
      </geometry>
    </visual>
    <visual>
      <origin xyz="0. 0.225 -0.002" rpy="-0. 0. 0."/>
      <geometry>
        <mesh filename="meshes/left_tibia_visuals_mesh_3.obj" scale="1. 1. 1."/>
      </geometry>
    </visual>
    <visual>
      <origin xyz="0. 0. -0.0327" rpy="-3.1415925 0. 0. "/>
      <geometry>
        <mesh filename="meshes/left_tibia_visuals_mesh_4.obj" scale="1. 1. 1."/>
      </geometry>
    </visual>
    <collision>
      <origin xyz="0. 0. -0.0327" rpy="-3.1415925 0. 0. "/>
      <geometry>
        <mesh filename="meshes/left_tibia_collisions_mesh_4.obj" scale="1. 1. 1."/>
      </geometry>
    </collision>
  </link>
  <link name="neck">
    <inertial>
      <origin xyz="0.0004892 -0.0017958 -0.02735 " rpy="0. 0. 0."/>
      <mass value="0.2942388"/>
      <inertia ixx="0.0001135" ixy="0.0000001" ixz="-0.0000017" iyy="0.000124" iyz="-0.0000033" izz="0.0001178"/>
    </inertial>
    <visual>
      <origin xyz="0. 0. 0." rpy="0. 0. 0."/>
      <geometry>
        <mesh filename="meshes/neck_visuals_mesh_0.obj" scale="1. 1. 1."/>
      </geometry>
    </visual>
    <visual>
      <origin xyz="0. -0.0109 -0.03 " rpy="-1.5707963 0. 0. "/>
      <geometry>
        <mesh filename="meshes/neck_visuals_mesh_1.obj" scale="1. 1. 1."/>
      </geometry>
    </visual>
    <visual>
      <origin xyz="0.0139599 0.0182 -0.0492141" rpy="-1.5707963 -0.0000002 -3.1415927"/>
      <geometry>
        <mesh filename="meshes/neck_visuals_mesh_2.obj" scale="1. 1. 1."/>
      </geometry>
    </visual>
    <visual>
      <origin xyz="0. 0.0212 -0.03 " rpy="1.5707966 -0.0000002 -3.1415927"/>
      <geometry>
        <mesh filename="meshes/neck_visuals_mesh_3.obj" scale="1. 1. 1."/>
      </geometry>
    </visual>
    <visual>
      <origin xyz="0. 0.0182 -0.03 " rpy="-1.5707959 -0.0000002 -3.1415927"/>
      <geometry>
        <mesh filename="meshes/neck_visuals_mesh_4.obj" scale="1. 1. 1."/>
      </geometry>
    </visual>
    <visual>
      <origin xyz="0. 0.0232 -0.03 " rpy="-1.5707959 -0.0000002 -3.1415927"/>
      <geometry>
        <mesh filename="meshes/neck_visuals_mesh_5.obj" scale="1. 1. 1."/>
      </geometry>
    </visual>
    <visual>
      <origin xyz="0. -0.0217 -0.03 " rpy="-1.5707963 0. -3.1415925"/>
      <geometry>
        <mesh filename="meshes/neck_visuals_mesh_6.obj" scale="1. 1. 1."/>
      </geometry>
    </visual>
    <visual>
      <origin xyz="0. -0.0217 -0.03 " rpy="-1.5707963 0. -3.1415925"/>
      <geometry>
        <mesh filename="meshes/neck_visuals_mesh_7.obj" scale="1. 1. 1."/>
      </geometry>
    </visual>
  </link>
  <link name="pelvis">
    <inertial>
      <origin xyz="-0.0008976 0.0000101 0.06071 " rpy="0. 0. 0."/>
      <mass value="1.6626244"/>
      <inertia ixx="0.0027912" ixy="-0.0000084" ixz="0.0000088" iyy="0.0025755" iyz="-0.0000074" izz="0.0024863"/>
    </inertial>
    <visual>
      <origin xyz="0. 0. 0." rpy="0. 0. 0."/>
      <geometry>
        <mesh filename="meshes/pelvis_visuals_mesh_0.obj" scale="1. 1. 1."/>
      </geometry>
    </visual>
    <visual>
      <origin xyz="0.02 0.0176 0.007 " rpy="1.5707963 0. 0. "/>
      <geometry>
        <mesh filename="meshes/pelvis_visuals_mesh_1.obj" scale="1. 1. 1."/>
      </geometry>
    </visual>
    <visual>
      <origin xyz="0.029 0. 0.0217" rpy="-1.5707965 0. 0. "/>
      <geometry>
        <mesh filename="meshes/pelvis_visuals_mesh_2.obj" scale="1. 1. 1."/>
      </geometry>
    </visual>
    <visual>
      <origin xyz="-0. -0.0123 0.0675" rpy="-2.6779451 -1.570796 1.1071486"/>
      <geometry>
        <mesh filename="meshes/pelvis_visuals_mesh_3.obj" scale="1. 1. 1."/>
      </geometry>
    </visual>
    <visual>
      <origin xyz="-0. -0.042 0.0675" rpy="0.4636477 -1.570796 1.1071488"/>
      <geometry>
        <mesh filename="meshes/pelvis_visuals_mesh_4.obj" scale="1. 1. 1."/>
      </geometry>
    </visual>
    <visual>
      <origin xyz="-0. -0.0123 0.0675" rpy="1.5707966 0.0000002 -3.1415927"/>
      <geometry>
        <mesh filename="meshes/pelvis_visuals_mesh_5.obj" scale="1. 1. 1."/>
      </geometry>
    </visual>
    <visual>
      <origin xyz="-0. 0.0123 0.0675" rpy="0.7853981 -1.5707961 0.7853981"/>
      <geometry>
        <mesh filename="meshes/pelvis_visuals_mesh_6.obj" scale="1. 1. 1."/>
      </geometry>
    </visual>
    <visual>
      <origin xyz="-0. 0.042 0.0675" rpy="1.5707966 -0.0000002 3.1415927"/>
      <geometry>
        <mesh filename="meshes/pelvis_visuals_mesh_7.obj" scale="1. 1. 1."/>
      </geometry>
    </visual>
  </link>
  <link name="right_femur_lower">
    <inertial>
      <origin xyz="0.0081757 0.0128823 0.052498 " rpy="0. 0. 0."/>
      <mass value="0.2734299"/>
      <inertia ixx="0.0005162" ixy="0.0000232" ixz="-0.0000633" iyy="0.0004878" iyz="-0.0000977" izz="0.0004289"/>
    </inertial>
    <visual>
      <origin xyz="0. -0. -0." rpy="0. 0. 0."/>
      <geometry>
        <mesh filename="meshes/right_femur_lower_visuals_mesh_0.obj" scale="1. 1. 1."/>
      </geometry>
    </visual>
    <visual>
      <origin xyz="0. -0. -0." rpy="0. 0. 0."/>
      <geometry>
        <mesh filename="meshes/right_femur_lower_visuals_mesh_1.obj" scale="1. 1. 1."/>
      </geometry>
    </visual>
  </link>
  <link name="right_femur_upper">
    <inertial>
      <origin xyz="0.0495475 -0.0002484 -0.0250827" rpy="0. 0. 0."/>
      <mass value="1.5005859"/>
      <inertia ixx="0.0017074" ixy="-0.0000397" ixz="0.0001185" iyy="0.0057616" iyz="-0.0000183" izz="0.005995"/>
    </inertial>
    <visual>
      <origin xyz="0. 0. 0." rpy="-0. -0. 0."/>
      <geometry>
        <mesh filename="meshes/right_femur_upper_visuals_mesh_0.obj" scale="1. 1. 1."/>
      </geometry>
    </visual>
    <visual>
      <origin xyz="0. 0. -0.009" rpy="0. -0. -1.5707961"/>
      <geometry>
        <mesh filename="meshes/right_femur_upper_visuals_mesh_1.obj" scale="1. 1. 1."/>
      </geometry>
    </visual>
    <visual>
      <origin xyz="0. 0. -0.009" rpy="-0. 0. 1.5707966"/>
      <geometry>
        <mesh filename="meshes/right_femur_upper_visuals_mesh_2.obj" scale="1. 1. 1."/>
      </geometry>
    </visual>
    <visual>
      <origin xyz="0. 0. -0.009" rpy="-0. 0. 1.5707963"/>
      <geometry>
        <mesh filename="meshes/right_femur_upper_visuals_mesh_3.obj" scale="1. 1. 1."/>
      </geometry>
    </visual>
    <visual>
      <origin xyz="0.145 -0. -0.021" rpy="1.1049286 -1.5707963 2.036664 "/>
      <geometry>
        <mesh filename="meshes/right_femur_upper_visuals_mesh_4.obj" scale="1. 1. 1."/>
      </geometry>
    </visual>
    <visual>
      <origin xyz="0.145 -0. -0.021" rpy="1.1049286 -1.5707963 2.036664 "/>
      <geometry>
        <mesh filename="meshes/right_femur_upper_visuals_mesh_5.obj" scale="1. 1. 1."/>
      </geometry>
    </visual>
    <collision>
      <origin xyz="0. 0. -0.009" rpy="0. -0. -1.5707961"/>
      <geometry>
        <mesh filename="meshes/right_femur_upper_collisions_mesh_1.obj" scale="1. 1. 1."/>
      </geometry>
    </collision>
  </link>
  <link name="right_foot">
    <inertial>
      <origin xyz="0.0186991 0.058262 -0.00597 " rpy="0. 0. 0."/>
      <mass value="0.3716065"/>
      <inertia ixx="0.0007716" ixy="-0.0000539" ixz="-0.000021" iyy="0.00055" iyz="-0.0000476" izz="0.0006226"/>
    </inertial>
    <visual>
      <origin xyz="-0. 0. 0." rpy="0. 0. 0."/>
      <geometry>
        <mesh filename="meshes/right_foot_visuals_mesh_0.obj" scale="1. 1. 1."/>
      </geometry>
    </visual>
    <visual>
      <origin xyz="0.057 0.066 -0.012" rpy="1.3256364 -1.5707963 0.2451599"/>
      <geometry>
        <mesh filename="meshes/right_foot_visuals_mesh_1.obj" scale="1. 1. 1."/>
      </geometry>
    </visual>
    <visual>
      <origin xyz="-0.039 0.069 -0.012" rpy="1.3256364 -1.5707963 0.2451599"/>
      <geometry>
        <mesh filename="meshes/right_foot_visuals_mesh_2.obj" scale="1. 1. 1."/>
      </geometry>
    </visual>
    <visual>
      <origin xyz="-0.039 0.072 -0.012" rpy="1.3256364 -1.5707963 0.2451599"/>
      <geometry>
        <mesh filename="meshes/right_foot_visuals_mesh_3.obj" scale="1. 1. 1."/>
      </geometry>
    </visual>
    <collision>
      <origin xyz="-0.039 0.072 -0.012" rpy="1.3256364 -1.5707963 0.2451599"/>
      <geometry>
        <mesh filename="meshes/right_foot_collisions_mesh_3.obj" scale="1. 1. 1."/>
      </geometry>
    </collision>
  </link>
  <link name="right_gripper_lower">
    <inertial>
      <origin xyz="0.0017305 -0.0059832 -0.0356482" rpy="0. 0. 0."/>
      <mass value="0.4099009"/>
      <inertia ixx="0.0002768" ixy="-0.0000573" ixz="0.0000295" iyy="0.0002508" iyz="0.0000031" izz="0.0002637"/>
    </inertial>
    <visual>
      <origin xyz="0. -0. 0." rpy="0. 0.0000001 0.0000001"/>
      <geometry>
        <mesh filename="meshes/right_gripper_lower_visuals_mesh_0.obj" scale="1. 1. 1."/>
      </geometry>
    </visual>
    <visual>
      <origin xyz="0.0107 -0.0139599 -0.0512141" rpy="1.5707961 0. -1.5707961"/>
      <geometry>
        <mesh filename="meshes/right_gripper_lower_visuals_mesh_1.obj" scale="1. 1. 1."/>
      </geometry>
    </visual>
    <visual>
      <origin xyz="-0.0184 0.0139599 -0.0512141" rpy="1.5707961 0. -1.5707961"/>
      <geometry>
        <mesh filename="meshes/right_gripper_lower_visuals_mesh_2.obj" scale="1. 1. 1."/>
      </geometry>
    </visual>
    <visual>
      <origin xyz="-0.0184 -0. -0.032 " rpy="-1.5707963 0.0000001 -1.5707961"/>
      <geometry>
        <mesh filename="meshes/right_gripper_lower_visuals_mesh_3.obj" scale="1. 1. 1."/>
      </geometry>
    </visual>
    <visual>
      <origin xyz="-0.0199 -0. -0.032 " rpy="-1.5707963 0.0000001 -1.5707961"/>
      <geometry>
        <mesh filename="meshes/right_gripper_lower_visuals_mesh_4.obj" scale="1. 1. 1."/>
      </geometry>
    </visual>
    <visual>
      <origin xyz="-0.0199 -0. -0.032 " rpy="1.5707965 -0. -1.5707963"/>
      <geometry>
        <mesh filename="meshes/right_gripper_lower_visuals_mesh_5.obj" scale="1. 1. 1."/>
      </geometry>
    </visual>
    <visual>
      <origin xyz="-0.0219 -0. -0.032 " rpy="-1.570796 0. -1.5707961"/>
      <geometry>
        <mesh filename="meshes/right_gripper_lower_visuals_mesh_6.obj" scale="1. 1. 1."/>
      </geometry>
    </visual>
    <visual>
      <origin xyz="-0.0239 -0. -0.032 " rpy="-1.5707963 0.0000001 -1.5707961"/>
      <geometry>
        <mesh filename="meshes/right_gripper_lower_visuals_mesh_7.obj" scale="1. 1. 1."/>
      </geometry>
    </visual>
    <visual>
      <origin xyz="0.0205 0. -0.032 " rpy="1.5707961 0. -1.5707961"/>
      <geometry>
        <mesh filename="meshes/right_gripper_lower_visuals_mesh_8.obj" scale="1. 1. 1."/>
      </geometry>
    </visual>
    <visual>
      <origin xyz="-0. -0.0333673 -0.0706747" rpy="-1.6231562 0.0000001 0.0000001"/>
      <geometry>
        <mesh filename="meshes/right_gripper_lower_visuals_mesh_9.obj" scale="1. 1. 1."/>
      </geometry>
    </visual>
    <visual>
      <origin xyz="-0.0149082 -0.0347293 -0.092864 " rpy="-3.0499604 0.0000001 0.0000001"/>
      <geometry>
        <mesh filename="meshes/right_gripper_lower_visuals_mesh_10.obj" scale="1. 1. 1."/>
      </geometry>
    </visual>
    <collision>
      <origin xyz="-0. -0.0333673 -0.0706747" rpy="-1.6231562 0.0000001 0.0000001"/>
      <geometry>
        <mesh filename="meshes/right_gripper_lower_collisions_mesh_9.obj" scale="1. 1. 1."/>
      </geometry>
    </collision>
  </link>
  <link name="right_gripper_upper">
    <inertial>
      <origin xyz="-0.0178005 -0.0462068 0.0246915" rpy="0. 0. 0."/>
      <mass value="0.2071514"/>
      <inertia ixx="0.0002307" ixy="-0.0000006" ixz="0.0000126" iyy="0.0001534" iyz="-0.0000533" izz="0.0002495"/>
    </inertial>
    <visual>
      <origin xyz="0. 0. 0." rpy="0. -0. 0.0000003"/>
      <geometry>
        <mesh filename="meshes/right_gripper_upper_visuals_mesh_0.obj" scale="1. 1. 1."/>
      </geometry>
    </visual>
    <visual>
      <origin xyz="-0.0278172 -0.0552397 0.025 " rpy="0.0481584 1.5707961 0.2226916"/>
      <geometry>
        <mesh filename="meshes/right_gripper_upper_visuals_mesh_1.obj" scale="1. 1. 1."/>
      </geometry>
    </visual>
    <visual>
      <origin xyz="-0.0205461 -0.0684639 0.0559893" rpy="3.1415913 1.4541259 1.8515402"/>
      <geometry>
        <mesh filename="meshes/right_gripper_upper_visuals_mesh_2.obj" scale="1. 1. 1."/>
      </geometry>
    </visual>
    <collision>
      <origin xyz="-0.0278172 -0.0552397 0.025 " rpy="0.0481584 1.5707961 0.2226916"/>
      <geometry>
        <mesh filename="meshes/right_gripper_upper_collisions_mesh_1.obj" scale="1. 1. 1."/>
      </geometry>
    </collision>
  </link>
  <link name="right_hip">
    <inertial>
      <origin xyz="-0.0187388 0. 0.0288834" rpy="0. 0. 0."/>
      <mass value="0.1825002"/>
      <inertia ixx="0.0001758" ixy="0." ixz="0.0000443" iyy="0.0001825" iyz="0." izz="0.0001051"/>
    </inertial>
    <visual>
      <origin xyz="0. 0. -0." rpy="-0. 0. 0."/>
      <geometry>
        <mesh filename="meshes/right_hip_visuals.obj" scale="1. 1. 1."/>
      </geometry>
    </visual>
  </link>
  <link name="right_humerus_lower">
    <inertial>
      <origin xyz="-0.0003585 -0.0008795 -0.0328351" rpy="0. 0. 0."/>
      <mass value="0.1065669"/>
      <inertia ixx="0.0000959" ixy="0.000003" ixz="-0.0000071" iyy="0.0001244" iyz="-0.0000044" izz="0.0000861"/>
    </inertial>
    <visual>
      <origin xyz="0. -0. 0." rpy="0. 0.0000001 -0. "/>
      <geometry>
        <mesh filename="meshes/right_humerus_lower_visuals_mesh_0.obj" scale="1. 1. 1."/>
      </geometry>
    </visual>
    <visual>
      <origin xyz="0. -0. 0." rpy="-0. -0.0000001 -3.1415925"/>
      <geometry>
        <mesh filename="meshes/right_humerus_lower_visuals_mesh_1.obj" scale="1. 1. 1."/>
      </geometry>
    </visual>
  </link>
  <link name="right_humerus_upper">
    <inertial>
      <origin xyz="-0.0449682 -0.0169877 -0.0261315" rpy="0. 0. 0."/>
      <mass value="0.9145362"/>
      <inertia ixx="0.0021422" ixy="-0.0003258" ixz="-0.0000517" iyy="0.0005161" iyz="-0.000184" izz="0.0021952"/>
    </inertial>
    <visual>
      <origin xyz="0. 0. -0." rpy="0. 0.0000001 -0. "/>
      <geometry>
        <mesh filename="meshes/right_humerus_upper_visuals_mesh_0.obj" scale="1. 1. 1."/>
      </geometry>
    </visual>
    <visual>
      <origin xyz="0. 0. -0." rpy="0. 0.0000001 0.2094391"/>
      <geometry>
        <mesh filename="meshes/right_humerus_upper_visuals_mesh_1.obj" scale="1. 1. 1."/>
      </geometry>
    </visual>
    <visual>
      <origin xyz="-0.0428391 -0.0071834 -0.02705 " rpy="-2.3413146 -1.5707961 -0.2068659"/>
      <geometry>
        <mesh filename="meshes/right_humerus_upper_visuals_mesh_2.obj" scale="1. 1. 1."/>
      </geometry>
    </visual>
    <visual>
      <origin xyz="-0.0497764 -0.0118627 -0.02705 " rpy="1.5707964 -0.0000001 2.1642084"/>
      <geometry>
        <mesh filename="meshes/right_humerus_upper_visuals_mesh_3.obj" scale="1. 1. 1."/>
      </geometry>
    </visual>
    <visual>
      <origin xyz="-0.0705023 -0.0258425 -0.02705 " rpy="0.5306467 -1.570796 0.0627654"/>
      <geometry>
        <mesh filename="meshes/right_humerus_upper_visuals_mesh_4.obj" scale="1. 1. 1."/>
      </geometry>
    </visual>
    <visual>
      <origin xyz="-0.103498 -0.0480984 -0.02705 " rpy="-2.3900769 1.5707963 -1.7966647"/>
      <geometry>
        <mesh filename="meshes/right_humerus_upper_visuals_mesh_5.obj" scale="1. 1. 1."/>
      </geometry>
    </visual>
    <visual>
      <origin xyz="-0.0497764 -0.0118627 -0.02705 " rpy="0.5306467 -1.570796 0.0627654"/>
      <geometry>
        <mesh filename="meshes/right_humerus_upper_visuals_mesh_6.obj" scale="1. 1. 1."/>
      </geometry>
    </visual>
    <visual>
      <origin xyz="-0.0497764 -0.0118627 -0.02705 " rpy="-1.300455 1.570796 2.4345496"/>
      <geometry>
        <mesh filename="meshes/right_humerus_upper_visuals_mesh_7.obj" scale="1. 1. 1."/>
      </geometry>
    </visual>
    <visual>
      <origin xyz="0. 0. -0." rpy="0. 0.0000001 0.2094391"/>
      <geometry>
        <mesh filename="meshes/right_humerus_upper_visuals_mesh_8.obj" scale="1. 1. 1."/>
      </geometry>
    </visual>
    <visual>
      <origin xyz="0. 0. -0." rpy="0. 0.0000001 0.2094391"/>
      <geometry>
        <mesh filename="meshes/right_humerus_upper_visuals_mesh_9.obj" scale="1. 1. 1."/>
      </geometry>
    </visual>
  </link>
  <link name="right_radius">
    <inertial>
      <origin xyz="-0.0149787 -0.0355595 -0.0260633" rpy="0. 0. 0."/>
      <mass value="0.7779886"/>
      <inertia ixx="0.0016748" ixy="-0.000189" ixz="-0.0000253" iyy="0.0003746" iyz="-0.0001229" izz="0.0017283"/>
    </inertial>
    <visual>
      <origin xyz="0. -0. -0." rpy="0. -0. 0."/>
      <geometry>
        <mesh filename="meshes/right_radius_visuals_mesh_0.obj" scale="1. 1. 1."/>
      </geometry>
    </visual>
    <visual>
      <origin xyz="0. -0. -0." rpy="-0. -0.0000001 1.0471977"/>
      <geometry>
        <mesh filename="meshes/right_radius_visuals_mesh_1.obj" scale="1. 1. 1."/>
      </geometry>
    </visual>
    <visual>
      <origin xyz="0. -0. -0." rpy="-0. -0.0000001 1.0471977"/>
      <geometry>
        <mesh filename="meshes/right_radius_visuals_mesh_2.obj" scale="1. 1. 1."/>
      </geometry>
    </visual>
    <visual>
      <origin xyz="0. -0. -0." rpy="-0. -0.0000001 1.0471977"/>
      <geometry>
        <mesh filename="meshes/right_radius_visuals_mesh_3.obj" scale="1. 1. 1."/>
      </geometry>
    </visual>
    <visual>
      <origin xyz="-0.0198133 -0.0353071 -0.02705 " rpy="1.8325958 1.5707963 0. "/>
      <geometry>
        <mesh filename="meshes/right_radius_visuals_mesh_4.obj" scale="1. 1. 1."/>
      </geometry>
    </visual>
    <visual>
      <origin xyz="-0.021979 -0.0433899 -0.02705 " rpy="1.5707964 0. -0.2617994"/>
      <geometry>
        <mesh filename="meshes/right_radius_visuals_mesh_5.obj" scale="1. 1. 1."/>
      </geometry>
    </visual>
    <visual>
      <origin xyz="-0.021979 -0.0433899 -0.02705 " rpy="1.8325958 1.5707963 0. "/>
      <geometry>
        <mesh filename="meshes/right_radius_visuals_mesh_6.obj" scale="1. 1. 1."/>
      </geometry>
    </visual>
    <visual>
      <origin xyz="-0.0284495 -0.067538 -0.02705 " rpy="1.5707964 0. -0.2617994"/>
      <geometry>
        <mesh filename="meshes/right_radius_visuals_mesh_7.obj" scale="1. 1. 1."/>
      </geometry>
    </visual>
    <visual>
      <origin xyz="-0.0374823 -0.1012488 -0.02705 " rpy="-1.3089968 1.5707963 0. "/>
      <geometry>
        <mesh filename="meshes/right_radius_visuals_mesh_8.obj" scale="1. 1. 1."/>
      </geometry>
    </visual>
    <visual>
      <origin xyz="-0.021979 -0.0433899 -0.02705 " rpy="-1.5707965 0.0000001 2.8797932"/>
      <geometry>
        <mesh filename="meshes/right_radius_visuals_mesh_9.obj" scale="1. 1. 1."/>
      </geometry>
    </visual>
    <collision>
      <origin xyz="0. -0. -0." rpy="-0. -0.0000001 1.0471977"/>
      <geometry>
        <mesh filename="meshes/right_radius_collisions_mesh_2.obj" scale="1. 1. 1."/>
      </geometry>
    </collision>
  </link>
  <link name="right_shoulder">
    <inertial>
      <origin xyz="-0.0002186 0.0080392 0.0284942" rpy="0. 0. 0."/>
      <mass value="0.1304355"/>
      <inertia ixx="0.0001096" ixy="-0.0000047" ixz="-0.0000066" iyy="0.0001508" iyz="-0.000016" izz="0.0001231"/>
    </inertial>
    <visual>
      <origin xyz="0. 0. 0." rpy="0. 0. 0."/>
      <geometry>
        <mesh filename="meshes/right_shoulder_visuals_mesh_0.obj" scale="1. 1. 1."/>
      </geometry>
    </visual>
    <visual>
      <origin xyz="0.0004109 0. 0. " rpy="0. 0. 0."/>
      <geometry>
        <mesh filename="meshes/right_shoulder_visuals_mesh_1.obj" scale="1. 1. 1."/>
      </geometry>
    </visual>
    <visual>
      <origin xyz="0.0004109 0. 0. " rpy="-3.1415925 0. 0. "/>
      <geometry>
        <mesh filename="meshes/right_shoulder_visuals_mesh_2.obj" scale="1. 1. 1."/>
      </geometry>
    </visual>
  </link>
  <link name="right_tibia">
    <inertial>
      <origin xyz="0.0002234 -0.1132653 -0.0181919" rpy="0. 0. 0."/>
      <mass value="1.7307752"/>
      <inertia ixx="0.0016867" ixy="-0.0008718" ixz="0.0000216" iyy="0.0199924" iyz="0.0000066" izz="0.0205309"/>
    </inertial>
    <visual>
      <origin xyz="-0. 0. 0." rpy="-0.0000001 0. 0. "/>
      <geometry>
        <mesh filename="meshes/right_tibia_visuals_mesh_0.obj" scale="1. 1. 1."/>
      </geometry>
    </visual>
    <visual>
      <origin xyz="-0. 0. -0.003" rpy="-0.0000001 0. 0. "/>
      <geometry>
        <mesh filename="meshes/right_tibia_visuals_mesh_1.obj" scale="1. 1. 1."/>
      </geometry>
    </visual>
    <visual>
      <origin xyz="-0. 0. -0.0327" rpy="-3.1415925 0. 0. "/>
      <geometry>
        <mesh filename="meshes/right_tibia_visuals_mesh_2.obj" scale="1. 1. 1."/>
      </geometry>
    </visual>
    <visual>
      <origin xyz="-0. -0.225 -0.002" rpy="-0.0000001 0. 0. "/>
      <geometry>
        <mesh filename="meshes/right_tibia_visuals_mesh_3.obj" scale="1. 1. 1."/>
      </geometry>
    </visual>
    <visual>
      <origin xyz="-0. 0. -0.0327" rpy="-3.1415925 0. 0. "/>
      <geometry>
        <mesh filename="meshes/right_tibia_visuals_mesh_4.obj" scale="1. 1. 1."/>
      </geometry>
    </visual>
    <collision>
      <origin xyz="-0. 0. -0.0327" rpy="-3.1415925 0. 0. "/>
      <geometry>
        <mesh filename="meshes/right_tibia_collisions_mesh_4.obj" scale="1. 1. 1."/>
      </geometry>
    </collision>
  </link>
</robot>
